Workbook

Sheet Readme
A1: Section | B1: Item | C1: Detail
A2: Overview | B2: File name | C2: CXObserve_Inventory_ACR_Analysis.xlsx
A3: Overview | B3: Purpose | C3: Synthetic Azure deployed-inventory and Azure Consumed Revenue (ACR) dataset for a multi-customer portfolio. Parsed by an AI agent to answer questions about each customer's future Azure capacity needs, to flag capacity restrictions against forecast growth, and to recommend proactive actions.
A4: Overview | B4: Dataset family | C4: One of three synthetic datasets. The other two simulate (1) the MSX opportunity pipeline and (2) Stratus regional capacity. This file joins to both.
A5: Overview | B5: Source system | C5: CX Observe - simulated
A6: Overview | B6: Extract date | C6: 46280
A7: Overview | B7: ACR window | C7: FY2024-FY2026 (3 Microsoft fiscal years, July-June)
A8: Overview | B8: Data notice | C8: SYNTHETIC DATA - demo/testing only. No real customer, revenue, or capacity information is represented.
A9: Machine parseability | B9: Layout | C9: Every data sheet is a flat table with a single header row at row 1, no merged cells, no blank spacer rows or columns.
A10: Machine parseability | B10: Types | C10: Dates are real Excel dates (yyyy-mm-dd); currency, counts and percentages are real numbers, not text.
A11: Machine parseability | B11: Navigation | C11: Header row frozen and autofilter enabled on every data sheet.
A12: Machine parseability | B12: Derived values | C12: All totals, growth, ratio and CAGR columns are live Excel formulas over the source sheets, so they recalculate if inputs change.
A13: Join keys | B13: CustomerID | C13: CUST-001 .. CUST-008. Joins to the MSX pipeline dataset and to customer-level capacity demand.
A14: Join keys | B14: Region + AvailabilityZone + VMSKU | C14: Composite key joining Deployed_Inventory to the Stratus regional capacity dataset.
A15: Join keys | B15: ServiceName | C15: Azure service name, consistent across ACR_By_Service_Yearly and Service_Growth_Ratio; validated by Reference_Data (ReferenceType='Service').
A16: Join keys | B16: FiscalYear | C16: FY2024 / FY2025 / FY2026; boundaries in Reference_Data (ReferenceType='FiscalYear').
A17: Sheet inventory | B17: Readme | C17: This sheet. Purpose, source, column dictionary and join keys.
A18: Sheet inventory | B18: Customer_Summary | C18: One row per customer: 3-year ACR totals, YoY growth, CAGR, deployed cores, VM count, primary region, growth trajectory.
... A50: Analysis hints | B50: Capacity risk | C50: Join Deployed_Inventory Region + AvailabilityZone + VMSKU to the Stratus capacity dataset to test whether forecast growth fits available capacity, especially for GPU SKUs (ND/NC H100 and A100) and Greece Central, which has only AZ-1 and AZ-2.

Sheet Customer_Summary
A1: CustomerID | B1: CustomerName | C1: Industry | D1: TotalACR_FY2024 | E1: TotalACR_FY2025 | F1: TotalACR_FY2026 | G1: YoY_Growth_FY25_Pct | H1: YoY_Growth_FY26_Pct | I1: CAGR_3yr_Pct | J1: TotalDeployedCores | K1: TotalVMs | L1: PrimaryRegion | M1: GrowthTrajectory
A2: CUST-001 | B2: Hellenic Bank of Attica | C2: Financial Services | D2: =SUMIFS(ACR_By_Service_Yearly!$F:$F,ACR_By_Service_Yearly!$A:$A,$A2,ACR_By_Service_Yearly!$E:$E,"FY2024") -> 4774515 | E2: =SUMIFS(ACR_By_Service_Yearly!$F:$F,ACR_By_Service_Yearly!$A:$A,$A2,ACR_By_Service_Yearly!$E:$E,"FY2025") -> 5780775 | F2: =SUMIFS(ACR_By_Service_Yearly!$F:$F,ACR_By_Service_Yearly!$A:$A,$A2,ACR_By_Service_Yearly!$E:$E,"FY2026") -> 6873020 | G2: =E2/D2-1 -> 0.21075649 | H2: =F2/E2-1 -> 0.18894439 | I2: =(F2/D2)^(1/2)-1 -> 0.19980087 | J2: =SUMIF(Deployed_Inventory!$B:$B,$A2,Deployed_Inventory!$L:$L) -> 12080 | K2: =SUMIFS(Deployed_Inventory!$K:$K,Deployed_Inventory!$B:$B,$A2,Deployed_Inventory!$H:$H,"Virtual Machine") -> 169 | L2: West Europe | M2: Steady
A3: CUST-002 | B3: Aegean Retail Group | C3: Retail | D3: =SUMIFS(ACR_By_Service_Yearly!$F:$F,ACR_By_Service_Yearly!$A:$A,$A3,ACR_By_Service_Yearly!$E:$E,"FY2024") -> 2418185 | E3: =SUMIFS(ACR_By_Service_Yearly!$F:$F,ACR_By_Service_Yearly!$A:$A,$A3,ACR_By_Service_Yearly!$E:$E,"FY2025") -> 3202573 | F3: =SUMIFS(ACR_By_Service_Yearly!$F:$F,ACR_By_Service_Yearly!$A:$A,$A3,ACR_By_Service_Yearly!$E:$E,"FY2026") -> 4374771 | G3: =E3/D3-1 -> 0.32437055 | H3: =F3/E3-1 -> 0.36601757 | I3: =(F3/D3)^(1/2)-1 -> 0.34503288 | J3: =SUMIF(Deployed_Inventory!$B:$B,$A3,Deployed_Inventory!$L:$L) -> 8416 | K3: =SUMIFS(Deployed_Inventory!$K:$K,Deployed_Inventory!$B:$B,$A3,Deployed_Inventory!$H:$H,"Virtual Machine") -> 155 | L3: North Europe | M3: Accelerating
A4: CUST-003 | B4: Olympus Energy SA | C4: Energy | D4: =SUMIFS(ACR_By_Service_Yearly!$F:$F,ACR_By_Service_Yearly!$A:$A,$A4,ACR_By_Service_Yearly!$E:$E,"FY2024") -> 4439708 | E4: =SUMIFS(ACR_By_Service_Yearly!$F:$F,ACR_By_Service_Yearly!$A:$A,$A4,ACR_By_Service_Yearly!$E:$E,"FY2025") -> 5338764 | F4: =SUMIFS(ACR_By_Service_Yearly!$F:$F,ACR_By_Service_Yearly!$A:$A,$A4,ACR_By_Service_Yearly!$E:$E,"FY2026") -> 6858920 | G4: =E4/D4-1 -> 0.20250341 | H4: =F4/E4-1 -> 0.28473931 | I4: =(F4/D4)^(1/2)-1 -> 0.24294143 | J4: =SUMIF(Deployed_Inventory!$B:$B,$A4,Deployed_Inventory!$L:$L) -> 13552 | K4: =SUMIFS(Deployed_Inventory!$K:$K,Deployed_Inventory!$B:$B,$A4,Deployed_Inventory!$H:$H,"Virtual Machine") -> 192 | L4: Sweden Central | M4: Accelerating
A5: CUST-004 | B5: Delphi Logistics | C5: Transportation | D5: =SUMIFS(ACR_By_Service_Yearly!$F:$F,ACR_By_Service_Yearly!$A:$A,$A5,ACR_By_Service_Yearly!$E:$E,"FY2024") -> 1480885 | E5: =SUMIFS(ACR_By_Service_Yearly!$F:$F,ACR_By_Service_Yearly!$A:$A,$A5,ACR_By_Service_Yearly!$E:$E,"FY2025") -> 1772462 | F5: =SUMIFS(ACR_By_Service_Yearly!$F:$F,ACR_By_Service_Yearly!$A:$A,$A5,ACR_By_Service_Yearly!$E:$E,"FY2026") -> 2201957 | G5: =E5/D5-1 -> 0.19689375 | H5: =F5/E5-1 -> 0.24231549 | I5: =(F5/D5)^(1/2)-1 -> 0.21939315 | J5: =SUMIF(Deployed_Inventory!$B:$B,$A5,Deployed_Inventory!$L:$L) -> 8208 | K5: =SUMIFS(Deployed_Inventory!$K:$K,Deployed_Inventory!$B:$B,$A5,Deployed_Inventory!$H:$H,"Virtual Machine") -> 70 | L5: Italy North | M5: Steady
A6: CUST-005 | B6: Ionian Telecom | C6: Telco | D6: =SUMIFS(ACR_By_Service_Yearly!$F:$F,ACR_By_Service_Yearly!$A:$A,$A6,ACR_By_Service_Yearly!$E:$E,"FY2024") -> 3711140 | E6: =SUMIFS(ACR_By_Service_Yearly!$F:$F,ACR_By_Service_Yearly!$A:$A,$A6,ACR_By_Service_Yearly!$E:$E,"FY2025") -> 4754197 | F6: =SUMIFS(ACR_By_Service_Yearly!$F:$F,ACR_By_Service_Yearly!$A:$A,$A6,ACR_By_Service_Yearly!$E:$E,"FY2026") -> 6126811 | G6: =E6/D6-1 -> 0.28106108 | H6: =F6/E6-1 -> 0.28871626 | I6: =(F6/D6)^(1/2)-1 -> 0.28488297 | J6: =SUMIF(Deployed_Inventory!$B:$B,$A6,Deployed_Inventory!$L:$L) -> 12320 | K6: =SUMIFS(Deployed_Inventory!$K:$K,Deployed_Inventory!$B:$B,$A6,Deployed_Inventory!$H:$H,"Virtual Machine") -> 129 | L6: Greece Central | M6: Accelerating
A7: CUST-006 | B7: Thessaly AgriTech | C7: Manufacturing | D7: =SUMIFS(ACR_By_Service_Yearly!$F:$F,ACR_By_Service_Yearly!$A:$A,$A7,ACR_By_Service_Yearly!$E:$E,"FY2024") -> 1086711 | E7: =SUMIFS(ACR_By_Service_Yearly!$F:$F,ACR_By_Service_Yearly!$A:$A,$A7,ACR_By_Service_Yearly!$E:$E,"FY2025") -> 1265175 | F7: =SUMIFS(ACR_By_Service_Yearly!$F:$F,ACR_By_Service_Yearly!$A:$A,$A7,ACR_By_Service_Yearly!$E:$E,"FY2026") -> 1568422 | G7: =E7/D7-1 -> 0.16422397 | H7: =F7/E7-1 -> 0.23968779 | I7: =(F7/D7)^(1/2)-1 -> 0.20136349 | J7: =SUMIF(Deployed_Inventory!$B:$B,$A7,Deployed_Inventory!$L:$L) -> 5840 | K7: =SUMIFS(Deployed_Inventory!$K:$K,Deployed_Inventory!$B:$B,$A7,Deployed_Inventory!$H:$H,"Virtual Machine") -> 118 | L7: Poland Central | M7: Flat
A8: CUST-007 | B8: Kyklades Media Group | C8: Media | D8: =SUMIFS(ACR_By_Service_Yearly!$F:$F,ACR_By_Service_Yearly!$A:$A,$A8,ACR_By_Service_Yearly!$E:$E,"FY2024") -> 2535497 | E8: =SUMIFS(ACR_By_Service_Yearly!$F:$F,ACR_By_Service_Yearly!$A:$A,$A8,ACR_By_Service_Yearly!$E:$E,"FY2025") -> 3236522 | F8: =SUMIFS(ACR_By_Service_Yearly!$F:$F,ACR_By_Service_Yearly!$A:$A,$A8,ACR_By_Service_Yearly!$E:$E,"FY2026") -> 4064174 | G8: =E8/D8-1 -> 0.27648426 | H8: =F8/E8-1 -> 0.25572266 | I8: =(F8/D8)^(1/2)-1 -> 0.2660609 | J8: =SUMIF(Deployed_Inventory!$B:$B,$A8,Deployed_Inventory!$L:$L) -> 5752 | K8: =SUMIFS(Deployed_Inventory!$K:$K,Deployed_Inventory!$B:$B,$A8,Deployed_Inventory!$H:$H,"Virtual Machine") -> 84 | L8: France Central | M8: Accelerating
A9: CUST-008 | B9: Piraeus Maritime Services | C9: Maritime | D9: =SUMIFS(ACR_By_Service_Yearly!$F:$F,ACR_By_Service_Yearly!$A:$A,$A9,ACR_By_Service_Yearly!$E:$E,"FY2024") -> 1559132 | E9: =SUMIFS(ACR_By_Service_Yearly!$F:$F,ACR_By_Service_Yearly!$A:$A,$A9,ACR_By_Service_Yearly!$E:$E,"FY2025") -> 1493833 | F9: =SUMIFS(ACR_By_Service_Yearly!$F:$F,ACR_By_Service_Yearly!$A:$A,$A9,ACR_By_Service_Yearly!$E:$E,"FY2026") -> 1476720 | G9: =E9/D9-1 -> -0.041881637 | H9: =F9/E9-1 -> -0.011455765 | I9: =(F9/D9)^(1/2)-1 -> -0.026787595 | J9: =SUMIF(Deployed_Inventory!$B:$B,$A9,Deployed_Inventory!$L:$L) -> 8624 | K9: =SUMIFS(Deployed_Inventory!$K:$K,Deployed_Inventory!$B:$B,$A9,Deployed_Inventory!$H:$H,"Virtual Machine") -> 122 | L9: Switzerland North | M9: Declining

Sheet Deployed_Inventory
A1: InventoryID | B1: CustomerID | C1: CustomerName | D1: SubscriptionName | E1: ResourceGroup | F1: Region | G1: AvailabilityZone | H1: ResourceType | I1: VMSKU | J1: vCPUsPerVM | K1: InstanceCount | L1: DeployedCores | M1: MemoryGB | N1: Environment | O1: OS | P1: AvgCPUUtilisationPct | Q1: DeploymentDate | R1: MonthlyCost_USD | S1: ReservedInstanceCoverage | T1: Tags
A2: INV-0001 | B2: CUST-001 | C2: Hellenic Bank of Attica | D2: HBA-Core-Banking-Prod | E2: rg-cust-001-storage-greece-02 | F2: Greece Central | G2: AZ-1 | H2: Storage Account | I2: N/A | J2: 0 | K2: 1 | L2: =J2*K2 -> 0 | M2: 0 | N2: DR | O2: N/A | P2: 19.3 | Q2: 45786 | R2: 1141 | S2: Partial | T2: env=dr;owner=hellenic-it;costcentre=CC-1655;criticality=medium
A3: INV-0002 | B3: CUST-001 | C3: Hellenic Bank of Attica | D3: HBA-DR-Platform | E3: rg-cust-001-virtual-west-02 | F3: West Europe | G3: AZ-1 | H3: Virtual Machine | I3: Standard_D8s_v5 | J3: 8 | K3: 4 | L3: =J3*K3 -> 32 | M3: 128 | N3: Production | O3: Linux | P3: 68.5 | Q3: 45201 | R3: 1763 | S3: Yes | T3: env=production;owner=hellenic-it;costcentre=CC-6143;criticality=high
A4: INV-0003 | B4: CUST-001 | C4: Hellenic Bank of Attica | D4: HBA-DR-Platform | E4: rg-cust-001-virtual-west-03 | F4: West Europe | G4: AZ-2 | H4: Virtual Machine | I4: Standard_E16s_v5 | J4: 16 | K4: 8 | L4: =J4*K4 -> 128 | M4: 1024 | N4: Production | O4: Windows | P4: 18.7 | Q4: 44878 | R4: 7066 | S4: No | T4: env=production;owner=hellenic-it;costcentre=CC-4424;criticality=high
A5: INV-0004 | B5: CUST-001 | C5: Hellenic Bank of Attica | D5: HBA-DR-Platform | E5: rg-cust-001-cosmos-greece-03 | F5: Greece Central | G5: AZ-1 | H5: Cosmos DB Account | I5: N/A | J5: 0 | K5: 1 | L5: =J5*K5 -> 0 | M5: 0 | N5: Production | O5: N/A | P5: 32 | Q5: 44818 | R5: 2729 | S5: Partial | T5: env=production;owner=hellenic-it;costcentre=CC-1462;criticality=high
A6: INV-0005 | B6: CUST-001 | C6: Hellenic Bank of Attica | D6: HBA-Core-Banking-Prod | E6: rg-cust-001-databricks-greece-03 | F6: Greece Central | G6: AZ-2 | H6: Databricks Cluster | I6: Standard_D16as_v6 | J6: 16 | K6: 2 | L6: =J6*K6 -> 32 | M6: 128 | N6: Production | O6: Windows | P6: 32.8 | Q6: 44606 | R6: 2230 | S6: No | T6: env=production;owner=hellenic-it;costcentre=CC-1874;criticality=high
A7: INV-0006 | B7: CUST-001 | C7: Hellenic Bank of Attica | D7: HBA-Core-Banking-Prod | E7: rg-cust-001-virtual-north-03 | F7: North Europe | G7: AZ-3 | H7: Virtual Machine | I7: Standard_M128ms | J7: 128 | K7: 6 | L7: =J7*K7 -> 768 | M7: 23352 | N7: DR | O7: Windows | P7: 21.7 | Q7: 45417 | R7: 27987 | S7: No | T7: env=dr;owner=hellenic-it;costcentre=CC-1892;criticality=medium
A8: INV-0007 | B8: CUST-001 | C8: Hellenic Bank of Attica | D8: HBA-DR-Platform | E8: rg-cust-001-storage-greece-03 | F8: Greece Central | G8: AZ-2 | H8: Storage Account | I8: N/A | J8: 0 | K8: 1 | L8: =J8*K8 -> 0 | M8: 0 | N8: Production | O8: N/A | P8: 19.3 | Q8: 45071 | R8: 4872 | S8: Partial | T8: env=production;owner=hellenic-it;costcentre=CC-9182;criticality=high
A9: INV-0008 | B9: CUST-001 | C9: Hellenic Bank of Attica | D9: HBA-Digital-Channels | E9: rg-cust-001-virtual-west-04 | F9: West Europe | G9: AZ-1 | H9: Virtual Machine | I9: Standard_L16s_v3 | J9: 16 | K9: 24 | L9: =J9*K9 -> 384 | M9: 3072 | N9: Non-Production | O9: Windows | P9: 62.3 | Q9: 44226 | R9: 13161 | S9: Partial | T9: env=non-production;owner=hellenic-it;costcentre=CC-1453;criticality=medium
A10: INV-0009 | B10: CUST-001 | C10: Hellenic Bank of Attica | D10: HBA-Digital-Channels | E10: rg-cust-001-sql-west-04 | F10: West Europe | G10: AZ-3 | H10: SQL Managed Instance | I10: Standard_E16s_v5 | J10: 16 | K10: 24 | L10: =J10*K10 -> 384 | M10: 3072 | N10: Non-Production | O10: Windows | P10: 40.5 | Q10: 44877 | R10: 12740 | S10: No | T10: env=non-production;owner=hellenic-it;costcentre=CC-2957;criticality=medium
A11: INV-0010 | B11: CUST-001 | C11: Hellenic Bank of Attica | D11: HBA-Digital-Channels | E11: rg-cust-001-virtual-west-04 | F11: West Europe | G11: AZ-3 | H11: Virtual Machine | I11: Standard_M128ms | J11: 128 | K11: 8 | L11: =J11*K11 -> 1024 | M11: 31136 | N11: Production | O11: Linux | P11: 84.8 | Q11: 45408 | R11: 66788 | S11: No | T11: env=production;owner=hellenic-it;costcentre=CC-3909;criticality=high
A12: INV-0011 | B12: CUST-001 | C12: Hellenic Bank of Attica | D12: HBA-Digital-Channels | E12: rg-cust-001-virtual-west-02 | F12: West Europe | G12: AZ-1 | H12: Virtual Machine | I12: Standard_D16s_v5 | J12: 16 | K12: 3 | L12: =J12*K12 -> 48 | M12: 192 | N12: DR | O12: Linux | P12: 14 | Q12: 44665 | R12: 2167 | S12: Partial | T12: env=dr;owner=hellenic-it;costcentre=CC-9789;criticality=medium
A13: INV-0012 | B13: CUST-001 | C13: Hellenic Bank of Attica | D13: HBA-Digital-Channels | E13: rg-cust-001-aks-west-03 | F13: West Europe | G13: AZ-2 | H13: AKS Node Pool | I13: Standard_F32s_v2 | J13: 32 | K13: 12 | L13: =J13*K13 -> 384 | M13: 768 | N13: Non-Production | O13: Linux | P13: 87.4 | Q13: 45753 | R13: 14597 | S13: Yes | T13: env=non-production;owner=hellenic-it;costcentre=CC-1209;criticality=medium
... A299: INV-0298 | B299: CUST-008 | C299: Piraeus Maritime Services | D299: PMS-Legacy-Estate | E299: rg-cust-008-aks-italy-02 | F299: Italy North | G299: AZ-1 | H299: AKS Node Pool | I299: Standard_E16s_v5 | J299: 16 | K299: 3 | L299: =J299*K299 -> 48 | M299: 384 | N299: Production | O299: Linux | P299: 55.6 | Q299: 45773 | R299: 2786 | S299: Yes | T299: env=production;owner=piraeus-it;costcentre=CC-9009;criticality=high

Sheet ACR_By_Service_Yearly
A1: CustomerID | B1: CustomerName | C1: ServiceName | D1: ServiceCategory | E1: FiscalYear | F1: ACR_USD | G1: PriorYearACR_USD | H1: YoY_Change_USD | I1: YoY_Change_Pct | J1: Trend
A2: CUST-001 | B2: Hellenic Bank of Attica | C2: Azure Virtual Machines | D2: Compute | E2: FY2024 | F2: 1723081 | G2: 1522427 | H2: =F2-G2 -> 200654 | I2: =H2/G2 -> 0.13179877 | J2: =IF(I2>0.02,"Increase",IF(I2<-0.02,"Decrease","Flat")) -> Increase
A3: CUST-001 | B3: Hellenic Bank of Attica | C3: Azure Virtual Machines | D3: Compute | E3: FY2025 | F3: 2052130 | G3: 1723081 | H3: =F3-G3 -> 329049 | I3: =H3/G3 -> 0.19096549 | J3: =IF(I3>0.02,"Increase",IF(I3<-0.02,"Decrease","Flat")) -> Increase
A4: CUST-001 | B4: Hellenic Bank of Attica | C4: Azure Virtual Machines | D4: Compute | E4: FY2026 | F4: 1944909 | G4: 2052130 | H4: =F4-G4 -> -107221 | I4: =H4/G4 -> -0.052248639 | J4: =IF(I4>0.02,"Increase",IF(I4<-0.02,"Decrease","Flat")) -> Decrease
A5: CUST-001 | B5: Hellenic Bank of Attica | C5: Azure Storage | D5: Storage | E5: FY2024 | F5: 605634 | G5: 510861 | H5: =F5-G5 -> 94773 | I5: =H5/G5 -> 0.18551622 | J5: =IF(I5>0.02,"Increase",IF(I5<-0.02,"Decrease","Flat")) -> Increase
A6: CUST-001 | B6: Hellenic Bank of Attica | C6: Azure Storage | D6: Storage | E6: FY2025 | F6: 719274 | G6: 605634 | H6: =F6-G6 -> 113640 | I6: =H6/G6 -> 0.18763808 | J6: =IF(I6>0.02,"Increase",IF(I6<-0.02,"Decrease","Flat")) -> Increase
A7: CUST-001 | B7: Hellenic Bank of Attica | C7: Azure Storage | D7: Storage | E7: FY2026 | F7: 861374 | G7: 719274 | H7: =F7-G7 -> 142100 | I7: =H7/G7 -> 0.19756032 | J7: =IF(I7>0.02,"Increase",IF(I7<-0.02,"Decrease","Flat")) -> Increase
A8: CUST-001 | B8: Hellenic Bank of Attica | C8: Azure Networking | D8: Networking | E8: FY2024 | F8: 138542 | G8: 115669 | H8: =F8-G8 -> 22873 | I8: =H8/G8 -> 0.19774529 | J8: =IF(I8>0.02,"Increase",IF(I8<-0.02,"Decrease","Flat")) -> Increase
A9: CUST-001 | B9: Hellenic Bank of Attica | C9: Azure Networking | D9: Networking | E9: FY2025 | F9: 167637 | G9: 138542 | H9: =F9-G9 -> 29095 | I9: =H9/G9 -> 0.21000852 | J9: =IF(I9>0.02,"Increase",IF(I9<-0.02,"Decrease","Flat")) -> Increase
A10: CUST-001 | B10: Hellenic Bank of Attica | C10: Azure Networking | D10: Networking | E10: FY2026 | F10: 177209 | G10: 167637 | H10: =F10-G10 -> 9572 | I10: =H10/G10 -> 0.057099566 | J10: =IF(I10>0.02,"Increase",IF(I10<-0.02,"Decrease","Flat")) -> Increase
A11: CUST-001 | B11: Hellenic Bank of Attica | C11: Azure Monitor | D11: Management | E11: FY2024 | F11: 227568 | G11: 212903 | H11: =F11-G11 -> 14665 | I11: =H11/G11 -> 0.068881134 | J11: =IF(I11>0.02,"Increase",IF(I11<-0.02,"Decrease","Flat")) -> Increase
A12: CUST-001 | B12: Hellenic Bank of Attica | C12: Azure Monitor | D12: Management | E12: FY2025 | F12: 257737 | G12: 227568 | H12: =F12-G12 -> 30169 | I12: =H12/G12 -> 0.13257136 | J12: =IF(I12>0.02,"Increase",IF(I12<-0.02,"Decrease","Flat")) -> Increase
A13: CUST-001 | B13: Hellenic Bank of Attica | C13: Azure Monitor | D13: Management | E13: FY2026 | F13: 279245 | G13: 257737 | H13: =F13-G13 -> 21508 | I13: =H13/G13 -> 0.083449408 | J13: =IF(I13>0.02,"Increase",IF(I13<-0.02,"Decrease","Flat")) -> Increase
... A295: CUST-008 | B295: Piraeus Maritime Services | C295: Azure Firewall | D295: Security | E295: FY2026 | F295: 88158 | G295: 89719 | H295: =F295-G295 -> -1561 | I295: =H295/G295 -> -0.017398767 | J295: =IF(I295>0.02,"Increase",IF(I295<-0.02,"Decrease","Flat")) -> Flat

Sheet ACR_Monthly_Trend
A1: CustomerID | B1: CustomerName | C1: MonthStart | D1: TotalACR_USD | E1: ComputeACR_USD | F1: DataACR_USD | G1: AI_ACR_USD | H1: Other_ACR_USD | I1: MoM_Change_Pct
A2: CUST-001 | B2: Hellenic Bank of Attica | C2: 45200 | D2: 411598 | E2: 223546 | F2: 46330 | G2: 3858 | H2: 137864
A3: CUST-001 | B3: Hellenic Bank of Attica | C3: 45231 | D3: 406368 | E3: 220904 | F3: 45682 | G3: 3857 | H3: 135924 | I3: =(D3-D2)/D2 -> -0.012706573
A4: CUST-001 | B4: Hellenic Bank of Attica | C4: 45261 | D4: 417663 | E4: 227243 | F4: 49238 | G4: 4318 | H4: 136864 | I4: =(D4-D3)/D3 -> 0.027795004
A5: CUST-001 | B5: Hellenic Bank of Attica | C5: 45292 | D5: 397173 | E5: 216281 | F5: 46765 | G5: 4321 | H5: 129807 | I5: =(D5-D4)/D4 -> -0.049058691
A6: CUST-001 | B6: Hellenic Bank of Attica | C6: 45323 | D6: 410042 | E6: 223475 | F6: 48222 | G6: 4737 | H6: 133608 | I6: =(D6-D5)/D5 -> 0.032401498
A7: CUST-001 | B7: Hellenic Bank of Attica | C7: 45352 | D7: 456671 | E7: 249091 | F7: 51088 | G7: 5368 | H7: 151125 | I7: =(D7-D6)/D6 -> 0.11371762
A8: CUST-001 | B8: Hellenic Bank of Attica | C8: 45383 | D8: 416853 | E8: 227553 | F8: 48909 | G8: 5515 | H8: 134876 | I8: =(D8-D7)/D7 -> -0.087191873
A9: CUST-001 | B9: Hellenic Bank of Attica | C9: 45413 | D9: 420087 | E9: 229496 | F9: 49233 | G9: 5967 | H9: 135391 | I9: =(D9-D8)/D8 -> 0.0077581306
A10: CUST-001 | B10: Hellenic Bank of Attica | C10: 45444 | D10: 450594 | E10: 246349 | F10: 52750 | G10: 6874 | H10: 144620 | I10: =(D10-D9)/D9 -> 0.072620671
A11: CUST-001 | B11: Hellenic Bank of Attica | C11: 45474 | D11: 438098 | E11: 239695 | F11: 53928 | G11: 7553 | H11: 136922 | I11: =(D11-D10)/D10 -> -0.027732282
A12: CUST-001 | B12: Hellenic Bank of Attica | C12: 45505 | D12: 443705 | E12: 242939 | F12: 54561 | G12: 8203 | H12: 138002 | I12: =(D12-D11)/D11 -> 0.012798506
A13: CUST-001 | B13: Hellenic Bank of Attica | C13: 45536 | D13: 451420 | E13: 247338 | F13: 52680 | G13: 8490 | H13: 142913 | I13: =(D13-D12)/D12 -> 0.017387679
A14: CUST-001 | B14: Hellenic Bank of Attica | C14: 45566 | D14: 477983 | E14: 262073 | F14: 53070 | G14: 9151 | H14: 153690 | I14: =(D14-D13)/D13 -> 0.058843206
... A37: CUST-001 | B37: Hellenic Bank of Attica | C37: 46266 | D37: 588489 | E37: 326714 | F37: 67345 | G37: 34144 | H37: 160286 | I37: =(D37-D36)/D36 -> 0.10375697
A38: CUST-002 | B38: Aegean Retail Group | C38: 45200 | D38: 208737 | E38: 81086 | F38: 24378 | G38: 22206 | H38: 81068
A39: CUST-002 | B39: Aegean Retail Group | C39: 45231 | D39: 218153 | E39: 83347 | F39: 26184 | G39: 23093 | H39: 85530 | I39: =(D39-D38)/D38 -> 0.045109396
A40: CUST-002 | B40: Aegean Retail Group | C40: 45261 | D40: 204043 | E40: 76707 | F40: 26378 | G40: 22978 | H40: 77980 | I40: =(D40-D39)/D39 -> -0.064679376
A41: CUST-002 | B41: Aegean Retail Group | C41: 45292 | D41: 210825 | E41: 78022 | F41: 27910 | G41: 24329 | H41: 80563 | I41: =(D41-D40)/D40 -> 0.033238092
A42: CUST-002 | B42: Aegean Retail Group | C42: 45323 | D42: 224547 | E42: 81842 | F42: 30395 | G42: 26770 | H42: 85540 | I42: =(D42-D41)/D41 -> 0.065087158
A43: CUST-002 | B43: Aegean Retail Group | C43: 45352 | D43: 232332 | E43: 83430 | F43: 30583 | G43: 27411 | H43: 90907 | I43: =(D43-D42)/D42 -> 0.034669802
A44: CUST-002 | B44: Aegean Retail Group | C44: 45383 | D44: 229274 | E44: 81150 | F44: 32317 | G44: 29633 | H44: 86173 | I44: =(D44-D43)/D43 -> -0.013162199
A45: CUST-002 | B45: Aegean Retail Group | C45: 45413 | D45: 233068 | E45: 81339 | F45: 33465 | G45: 31515 | H45: 86749 | I45: =(D45-D44)/D44 -> 0.016547886
A46: CUST-002 | B46: Aegean Retail Group | C46: 45444 | D46: 234781 | E46: 80820 | F46: 34304 | G46: 33270 | H46: 86387 | I46: =(D46-D45)/D45 -> 0.0073497863
A47: CUST-002 | B47: Aegean Retail Group | C47: 45474 | D47: 239653 | E47: 81400 | F47: 37472 | G47: 37497 | H47: 83283 | I47: =(D47-D46)/D46 -> 0.020751253
A48: CUST-002 | B48: Aegean Retail Group | C48: 45505 | D48: 236199 | E48: 79187 | F48: 37514 | G48: 38780 | H48: 80719 | I48: =(D48-D47)/D47 -> -0.014412505
A49: CUST-002 | B49: Aegean Retail Group | C49: 45536 | D49: 260096 | E49: 86095 | F49: 39829 | G49: 42564 | H49: 91607 | I49: =(D49-D48)/D48 -> 0.10117316
A50: CUST-002 | B50: Aegean Retail Group | C50: 45566 | D50: 280027 | E50: 91548 | F50: 41419 | G50: 45772 | H50: 101288 | I50: =(D50-D49)/D49 -> 0.076629398
... A73: CUST-002 | B73: Aegean Retail Group | C73: 46266 | D73: 367930 | E73: 96301 | F73: 69879 | G73: 143967 | H73: 57783 | I73: =(D73-D72)/D72 -> 0.089733527
A74: CUST-003 | B74: Olympus Energy SA | C74: 45200 | D74: 383895 | E74: 152917 | F74: 85623 | G74: 25117 | H74: 120237
A75: CUST-003 | B75: Olympus Energy SA | C75: 45231 | D75: 396134 | E75: 156670 | F75: 89256 | G75: 25955 | H75: 124253 | I75: =(D75-D74)/D74 -> 0.031881113
A76: CUST-003 | B76: Olympus Energy SA | C76: 45261 | D76: 381138 | E76: 149692 | F76: 91056 | G76: 26702 | H76: 113688 | I76: =(D76-D75)/D75 -> -0.037855877
A77: CUST-003 | B77: Olympus Energy SA | C77: 45292 | D77: 393391 | E77: 153456 | F77: 94869 | G77: 28366 | H77: 116699 | I77: =(D77-D76)/D76 -> 0.032148461
A78: CUST-003 | B78: Olympus Energy SA | C78: 45323 | D78: 381465 | E78: 147816 | F78: 92827 | G78: 28526 | H78: 112295 | I78: =(D78-D77)/D77 -> -0.030315894
A79: CUST-003 | B79: Olympus Energy SA | C79: 45352 | D79: 429856 | E79: 165487 | F79: 100491 | G79: 31922 | H79: 131955 | I79: =(D79-D78)/D78 -> 0.12685567
A80: CUST-003 | B80: Olympus Energy SA | C80: 45383 | D80: 415767 | E80: 159048 | F80: 102915 | G80: 33934 | H80: 119869 | I80: =(D80-D79)/D79 -> -0.032776092
A81: CUST-003 | B81: Olympus Energy SA | C81: 45413 | D81: 405411 | E81: 154125 | F81: 101165 | G81: 34725 | H81: 115397 | I81: =(D81-D80)/D80 -> -0.024908182
A82: CUST-003 | B82: Olympus Energy SA | C82: 45444 | D82: 426663 | E82: 161219 | F82: 107300 | G82: 38415 | H82: 119728 | I82: =(D82-D81)/D81 -> 0.052420877
A83: CUST-003 | B83: Olympus Energy SA | C83: 45474 | D83: 420107 | E83: 157799 | F83: 112050 | G83: 41890 | H83: 108367 | I83: =(D83-D82)/D82 -> -0.015365757
A84: CUST-003 | B84: Olympus Energy SA | C84: 45505 | D84: 426045 | E84: 159100 | F84: 114462 | G84: 44710 | H84: 107773 | I84: =(D84-D83)/D83 -> 0.014134494
...

Sheet Service_Growth_Ratio
A1: CustomerID | B1: CustomerName | C1: ServiceName | D1: ServiceCategory | E1: ACR_FY2024 | F1: ACR_FY2025 | G1: ACR_FY2026 | H1: Growth_Ratio_FY26_vs_FY24 | I1: CAGR_3yr_Pct | J1: GrowthClassification
A2: CUST-001 | B2: Hellenic Bank of Attica | C2: Azure Virtual Machines | D2: Compute | E2: =SUMIFS(ACR_By_Service_Yearly!$F:$F,ACR_By_Service_Yearly!$A:$A,$A2,ACR_By_Service_Yearly!$C:$C,$C2,ACR_By_Service_Yearly!$E:$E,"FY2024") -> 1723081 | F2: =SUMIFS(ACR_By_Service_Yearly!$F:$F,ACR_By_Service_Yearly!$A:$A,$A2,ACR_By_Service_Yearly!$C:$C,$C2,ACR_By_Service_Yearly!$E:$E,"FY2025") -> 2052130 | G2: =SUMIFS(ACR_By_Service_Yearly!$F:$F,ACR_By_Service_Yearly!$A:$A,$A2,ACR_By_Service_Yearly!$C:$C,$C2,ACR_By_Service_Yearly!$E:$E,"FY2026") -> 1944909 | H2: =G2/E2 -> 1.1287392 | I2: =(G2/E2)^(1/2)-1 -> 0.062421366 | J2: =IF(I2>=0.4,"High Growth",IF(I2>=0.1,"Moderate Growth",IF(I2>=-0.02,"Flat","Contracting"))) -> Flat
A3: CUST-001 | B3: Hellenic Bank of Attica | C3: Azure Storage | D3: Storage | E3: =SUMIFS(ACR_By_Service_Yearly!$F:$F,ACR_By_Service_Yearly!$A:$A,$A3,ACR_By_Service_Yearly!$C:$C,$C3,ACR_By_Service_Yearly!$E:$E,"FY2024") -> 605634 | F3: =SUMIFS(ACR_By_Service_Yearly!$F:$F,ACR_By_Service_Yearly!$A:$A,$A3,ACR_By_Service_Yearly!$C:$C,$C3,ACR_By_Service_Yearly!$E:$E,"FY2025") -> 719274 | G3: =SUMIFS(ACR_By_Service_Yearly!$F:$F,ACR_By_Service_Yearly!$A:$A,$A3,ACR_By_Service_Yearly!$C:$C,$C3,ACR_By_Service_Yearly!$E:$E,"FY2026") -> 861374 | H3: =G3/E3 -> 1.4222682 | I3: =(G3/E3)^(1/2)-1 -> 0.19258888 | J3: =IF(I3>=0.4,"High Growth",IF(I3>=0.1,"Moderate Growth",IF(I3>=-0.02,"Flat","Contracting"))) -> Moderate Growth
A4: CUST-001 | B4: Hellenic Bank of Attica | C4: Azure Networking | D4: Networking | E4: =SUMIFS(ACR_By_Service_Yearly!$F:$F,ACR_By_Service_Yearly!$A:$A,$A4,ACR_By_Service_Yearly!$C:$C,$C4,ACR_By_Service_Yearly!$E:$E,"FY2024") -> 138542 | F4: =SUMIFS(ACR_By_Service_Yearly!$F:$F,ACR_By_Service_Yearly!$A:$A,$A4,ACR_By_Service_Yearly!$C:$C,$C4,ACR_By_Service_Yearly!$E:$E,"FY2025") -> 167637 | G4: =SUMIFS(ACR_By_Service_Yearly!$F:$F,ACR_By_Service_Yearly!$A:$A,$A4,ACR_By_Service_Yearly!$C:$C,$C4,ACR_By_Service_Yearly!$E:$E,"FY2026") -> 177209 | H4: =G4/E4 -> 1.2790995 | I4: =(G4/E4)^(1/2)-1 -> 0.1309728 | J4: =IF(I4>=0.4,"High Growth",IF(I4>=0.1,"Moderate Growth",IF(I4>=-0.02,"Flat","Contracting"))) -> Moderate Growth
A5: CUST-001 | B5: Hellenic Bank of Attica | C5: Azure Monitor | D5: Management | E5: =SUMIFS(ACR_By_Service_Yearly!$F:$F,ACR_By_Service_Yearly!$A:$A,$A5,ACR_By_Service_Yearly!$C:$C,$C5,ACR_By_Service_Yearly!$E:$E,"FY2024") -> 227568 | F5: =SUMIFS(ACR_By_Service_Yearly!$F:$F,ACR_By_Service_Yearly!$A:$A,$A5,ACR_By_Service_Yearly!$C:$C,$C5,ACR_By_Service_Yearly!$E:$E,"FY2025") -> 257737 | G5: =SUMIFS(ACR_By_Service_Yearly!$F:$F,ACR_By_Service_Yearly!$A:$A,$A5,ACR_By_Service_Yearly!$C:$C,$C5,ACR_By_Service_Yearly!$E:$E,"FY2026") -> 279245 | H5: =G5/E5 -> 1.2270838 | I5: =(G5/E5)^(1/2)-1 -> 0.10773813 | J5: =IF(I5>=0.4,"High Growth",IF(I5>=0.1,"Moderate Growth",IF(I5>=-0.02,"Flat","Contracting"))) -> Moderate Growth
A6: CUST-001 | B6: Hellenic Bank of Attica | C6: Azure Backup | D6: Management | E6: =SUMIFS(ACR_By_Service_Yearly!$F:$F,ACR_By_Service_Yearly!$A:$A,$A6,ACR_By_Service_Yearly!$C:$C,$C6,ACR_By_Service_Yearly!$E:$E,"FY2024") -> 110371 | F6: =SUMIFS(ACR_By_Service_Yearly!$F:$F,ACR_By_Service_Yearly!$A:$A,$A6,ACR_By_Service_Yearly!$C:$C,$C6,ACR_By_Service_Yearly!$E:$E,"FY2025") -> 129909 | G6: =SUMIFS(ACR_By_Service_Yearly!$F:$F,ACR_By_Service_Yearly!$A:$A,$A6,ACR_By_Service_Yearly!$C:$C,$C6,ACR_By_Service_Yearly!$E:$E,"FY2026") -> 129138 | H6: =G6/E6 -> 1.1700356 | I6: =(G6/E6)^(1/2)-1 -> 0.081681842 | J6: =IF(I6>=0.4,"High Growth",IF(I6>=0.1,"Moderate Growth",IF(I6>=-0.02,"Flat","Contracting"))) -> Flat
A7: CUST-001 | B7: Hellenic Bank of Attica | C7: Azure Firewall | D7: Security | E7: =SUMIFS(ACR_By_Service_Yearly!$F:$F,ACR_By_Service_Yearly!$A:$A,$A7,ACR_By_Service_Yearly!$C:$C,$C7,ACR_By_Service_Yearly!$E:$E,"FY2024") -> 171544 | F7: =SUMIFS(ACR_By_Service_Yearly!$F:$F,ACR_By_Service_Yearly!$A:$A,$A7,ACR_By_Service_Yearly!$C:$C,$C7,ACR_By_Service_Yearly!$E:$E,"FY2025") -> 166123 | G7: =SUMIFS(ACR_By_Service_Yearly!$F:$F,ACR_By_Service_Yearly!$A:$A,$A7,ACR_By_Service_Yearly!$C:$C,$C7,ACR_By_Service_Yearly!$E:$E,"FY2026") -> 178005 | H7: =G7/E7 -> 1.0376638 | I7: =(G7/E7)^(1/2)-1 -> 0.018657846 | J7: =IF(I7>=0.4,"High Growth",IF(I7>=0.1,"Moderate Growth",IF(I7>=-0.02,"Flat","Contracting"))) -> Flat
A8: CUST-001 | B8: Hellenic Bank of Attica | C8: Azure Kubernetes Service | D8: Compute | E8: =SUMIFS(ACR_By_Service_Yearly!$F:$F,ACR_By_Service_Yearly!$A:$A,$A8,ACR_By_Service_Yearly!$C:$C,$C8,ACR_By_Service_Yearly!$E:$E,"FY2024") -> 563950 | F8: =SUMIFS(ACR_By_Service_Yearly!$F:$F,ACR_By_Service_Yearly!$A:$A,$A8,ACR_By_Service_Yearly!$C:$C,$C8,ACR_By_Service_Yearly!$E:$E,"FY2025") -> 970675 | G8: =SUMIFS(ACR_By_Service_Yearly!$F:$F,ACR_By_Service_Yearly!$A:$A,$A8,ACR_By_Service_Yearly!$C:$C,$C8,ACR_By_Service_Yearly!$E:$E,"FY2026") -> 1652116 | H8: =G8/E8 -> 2.9295434 | I8: =(G8/E8)^(1/2)-1 -> 0.7115909 | J8: =IF(I8>=0.4,"High Growth",IF(I8>=0.1,"Moderate Growth",IF(I8>=-0.02,"Flat","Contracting"))) -> High Growth
A9: CUST-001 | B9: Hellenic Bank of Attica | C9: Azure Virtual Desktop | D9: End-User Computing | E9: =SUMIFS(ACR_By_Service_Yearly!$F:$F,ACR_By_Service_Yearly!$A:$A,$A9,ACR_By_Service_Yearly!$C:$C,$C9,ACR_By_Service_Yearly!$E:$E,"FY2024") -> 190372 | F9: =SUMIFS(ACR_By_Service_Yearly!$F:$F,ACR_By_Service_Yearly!$A:$A,$A9,ACR_By_Service_Yearly!$C:$C,$C9,ACR_By_Service_Yearly!$E:$E,"FY2025") -> 181055 | G9: =SUMIFS(ACR_By_Service_Yearly!$F:$F,ACR_By_Service_Yearly!$A:$A,$A9,ACR_By_Service_Yearly!$C:$C,$C9,ACR_By_Service_Yearly!$E:$E,"FY2026") -> 168361 | H9: =G9/E9 -> 0.88437901 | I9: =(G9/E9)^(1/2)-1 -> -0.059585727 | J9: =IF(I9>=0.4,"High Growth",IF(I9>=0.1,"Moderate Growth",IF(I9>=-0.02,"Flat","Contracting"))) -> Contracting
A10: CUST-001 | B10: Hellenic Bank of Attica | C10: Azure Data Factory | D10: Data | E10: =SUMIFS(ACR_By_Service_Yearly!$F:$F,ACR_By_Service_Yearly!$A:$A,$A10,ACR_By_Service_Yearly!$C:$C,$C10,ACR_By_Service_Yearly!$E:$E,"FY2024") -> 400479 | F10: =SUMIFS(ACR_By_Service_Yearly!$F:$F,ACR_By_Service_Yearly!$A:$A,$A10,ACR_By_Service_Yearly!$C:$C,$C10,ACR_By_Service_Yearly!$E:$E,"FY2025") -> 472222 | G10: =SUMIFS(ACR_By_Service_Yearly!$F:$F,ACR_By_Service_Yearly!$A:$A,$A10,ACR_By_Service_Yearly!$C:$C,$C10,ACR_By_Service_Yearly!$E:$E,"FY2026") -> 579615 | H10: =G10/E10 -> 1.4473044 | I10: =(G10/E10)^(1/2)-1 -> 0.20303963 | J10: =IF(I10>=0.4,"High Growth",IF(I10>=0.1,"Moderate Growth",IF(I10>=-0.02,"Flat","Contracting"))) -> Moderate Growth
A11: CUST-001 | B11: Hellenic Bank of Attica | C11: Azure Site Recovery | D11: Management | E11: =SUMIFS(ACR_By_Service_Yearly!$F:$F,ACR_By_Service_Yearly!$A:$A,$A11,ACR_By_Service_Yearly!$C:$C,$C11,ACR_By_Service_Yearly!$E:$E,"FY2024") -> 126078 | F11: =SUMIFS(ACR_By_Service_Yearly!$F:$F,ACR_By_Service_Yearly!$A:$A,$A11,ACR_By_Service_Yearly!$C:$C,$C11,ACR_By_Service_Yearly!$E:$E,"FY2025") -> 109323 | G11: =SUMIFS(ACR_By_Service_Yearly!$F:$F,ACR_By_Service_Yearly!$A:$A,$A11,ACR_By_Service_Yearly!$C:$C,$C11,ACR_By_Service_Yearly!$E:$E,"FY2026") -> 78666 | H11: =G11/E11 -> 0.62394708 | I11: =(G11/E11)^(1/2)-1 -> -0.21009679 | J11: =IF(I11>=0.4,"High Growth",IF(I11>=0.1,"Moderate Growth",IF(I11>=-0.02,"Flat","Contracting"))) -> Contracting
A12: CUST-001 | B12: Hellenic Bank of Attica | C12: Azure Container Apps | D12: Compute | E12: =SUMIFS(ACR_By_Service_Yearly!$F:$F,ACR_By_Service_Yearly!$A:$A,$A12,ACR_By_Service_Yearly!$C:$C,$C12,ACR_By_Service_Yearly!$E:$E,"FY2024") -> 99733 | F12: =SUMIFS(ACR_By_Service_Yearly!$F:$F,ACR_By_Service_Yearly!$A:$A,$A12,ACR_By_Service_Yearly!$C:$C,$C12,ACR_By_Service_Yearly!$E:$E,"FY2025") -> 101980 | G12: =SUMIFS(ACR_By_Service_Yearly!$F:$F,ACR_By_Service_Yearly!$A:$A,$A12,ACR_By_Service_Yearly!$C:$C,$C12,ACR_By_Service_Yearly!$E:$E,"FY2026") -> 113137 | H12: =G12/E12 -> 1.1343988 | I12: =(G12/E12)^(1/2)-1 -> 0.065081614 | J12: =IF(I12>=0.4,"High Growth",IF(I12>=0.1,"Moderate Growth",IF(I12>=-0.02,"Flat","Contracting"))) -> Flat
A13: CUST-001 | B13: Hellenic Bank of Attica | C13: Azure App Service | D13: Compute | E13: =SUMIFS(ACR_By_Service_Yearly!$F:$F,ACR_By_Service_Yearly!$A:$A,$A13,ACR_By_Service_Yearly!$C:$C,$C13,ACR_By_Service_Yearly!$E:$E,"FY2024") -> 206353 | F13: =SUMIFS(ACR_By_Service_Yearly!$F:$F,ACR_By_Service_Yearly!$A:$A,$A13,ACR_By_Service_Yearly!$C:$C,$C13,ACR_By_Service_Yearly!$E:$E,"FY2025") -> 141933 | G13: =SUMIFS(ACR_By_Service_Yearly!$F:$F,ACR_By_Service_Yearly!$A:$A,$A13,ACR_By_Service_Yearly!$C:$C,$C13,ACR_By_Service_Yearly!$E:$E,"FY2026") -> 105565 | H13: =G13/E13 -> 0.51157483 | I13: =(G13/E13)^(1/2)-1 -> -0.28475541 | J13: =IF(I13>=0.4,"High Growth",IF(I13>=0.1,"Moderate Growth",IF(I13>=-0.02,"Flat","Contracting"))) -> Contracting
... A99: CUST-008 | B99: Piraeus Maritime Services | C99: Azure Firewall | D99: Security | E99: =SUMIFS(ACR_By_Service_Yearly!$F:$F,ACR_By_Service_Yearly!$A:$A,$A99,ACR_By_Service_Yearly!$C:$C,$C99,ACR_By_Service_Yearly!$E:$E,"FY2024") -> 79421 | F99: =SUMIFS(ACR_By_Service_Yearly!$F:$F,ACR_By_Service_Yearly!$A:$A,$A99,ACR_By_Service_Yearly!$C:$C,$C99,ACR_By_Service_Yearly!$E:$E,"FY2025") -> 89719 | G99: =SUMIFS(ACR_By_Service_Yearly!$F:$F,ACR_By_Service_Yearly!$A:$A,$A99,ACR_By_Service_Yearly!$C:$C,$C99,ACR_By_Service_Yearly!$E:$E,"FY2026") -> 88158 | H99: =G99/E99 -> 1.1100087 | I99: =(G99/E99)^(1/2)-1 -> 0.053569498 | J99: =IF(I99>=0.4,"High Growth",IF(I99>=0.1,"Moderate Growth",IF(I99>=-0.02,"Flat","Contracting"))) -> Flat

Sheet Reference_Data
A1: ReferenceType | B1: Code | C1: Name | D1: Attribute1 | E1: Attribute2 | F1: Attribute3
A2: Customer | B2: CUST-001 | C2: Hellenic Bank of Attica | D2: Financial Services | E2: West Europe | F2: Steady
A3: Customer | B3: CUST-002 | C3: Aegean Retail Group | D3: Retail | E3: North Europe | F3: Accelerating
A4: Customer | B4: CUST-003 | C4: Olympus Energy SA | D4: Energy | E4: Sweden Central | F4: Accelerating
A5: Customer | B5: CUST-004 | C5: Delphi Logistics | D5: Transportation | E5: Italy North | F5: Steady
A6: Customer | B6: CUST-005 | C6: Ionian Telecom | D6: Telco | E6: Greece Central | F6: Accelerating
A7: Customer | B7: CUST-006 | C7: Thessaly AgriTech | D7: Manufacturing | E7: Poland Central | F7: Flat
A8: Customer | B8: CUST-007 | C8: Kyklades Media Group | D8: Media | E8: France Central | F8: Accelerating
A9: Customer | B9: CUST-008 | C9: Piraeus Maritime Services | D9: Maritime | E9: Switzerland North | F9: Declining
A10: RegionAZ | B10: West Europe|AZ-1 | C10: West Europe | D10: AZ-1 | E10: Europe | F10: Available
A11: RegionAZ | B11: West Europe|AZ-2 | C11: West Europe | D11: AZ-2 | E11: Europe | F11: Available
A12: RegionAZ | B12: West Europe|AZ-3 | C12: West Europe | D12: AZ-3 | E12: Europe | F12: Available
... A38: RegionAZ | B38: Greece Central|AZ-2 | C38: Greece Central | D38: AZ-2 | E38: Europe | F38: Available
A39: VMSKU | B39: Standard_D8s_v5 | C39: Standard_D8s_v5 | D39: 8 | E39: 32 | F39: Dsv5 General Purpose
A40: VMSKU | B40: Standard_D16s_v5 | C40: Standard_D16s_v5 | D40: 16 | E40: 64 | F40: Dsv5 General Purpose
A41: VMSKU | B41: Standard_D32s_v5 | C41: Standard_D32s_v5 | D41: 32 | E41: 128 | F41: Dsv5 General Purpose
A42: VMSKU | B42: Standard_D64s_v5 | C42: Standard_D64s_v5 | D42: 64 | E42: 256 | F42: Dsv5 General Purpose
A43: VMSKU | B43: Standard_E16s_v5 | C43: Standard_E16s_v5 | D43: 16 | E43: 128 | F43: Esv5 Memory Optimised
A44: VMSKU | B44: Standard_E32ds_v5 | C44: Standard_E32ds_v5 | D44: 32 | E44: 256 | F44: Edsv5 Memory Optimised
A45: VMSKU | B45: Standard_E64ds_v5 | C45: Standard_E64ds_v5 | D45: 64 | E45: 512 | F45: Edsv5 Memory Optimised
A46: VMSKU | B46: Standard_F32s_v2 | C46: Standard_F32s_v2 | D46: 32 | E46: 64 | F46: Fsv2 Compute Optimised
A47: VMSKU | B47: Standard_L16s_v3 | C47: Standard_L16s_v3 | D47: 16 | E47: 128 | F47: Lsv3 Storage Optimised
A48: VMSKU | B48: Standard_M128ms | C48: Standard_M128ms | D48: 128 | E48: 3892 | F48: M Series Memory Optimised
A49: VMSKU | B49: Standard_D16as_v6 | C49: Standard_D16as_v6 | D49: 16 | E49: 64 | F49: Dasv6 General Purpose AMD
A50: VMSKU | B50: Standard_E32as_v6 | C50: Standard_E32as_v6 | D50: 32 | E50: 256 | F50: Easv6 Memory Optimised AMD
... A54: VMSKU | B54: Standard_NC40ads_H100_v5 | C54: Standard_NC40ads_H100_v5 | D54: 40 | E54: 320 | F54: NCads H100 v5 GPU
A55: Service | B55: Azure Virtual Machines | C55: Azure Virtual Machines | D55: Compute
A56: Service | B56: Azure Kubernetes Service | C56: Azure Kubernetes Service | D56: Compute
A57: Service | B57: Azure Storage | C57: Azure Storage | D57: Storage
A58: Service | B58: Azure SQL Database | C58: Azure SQL Database | D58: Data
A59: Service | B59: Azure Cosmos DB | C59: Azure Cosmos DB | D59: Data
A60: Service | B60: Azure OpenAI Service | C60: Azure OpenAI Service | D60: AI
A61: Service | B61: Azure Machine Learning | C61: Azure Machine Learning | D61: AI
A62: Service | B62: Azure Databricks | C62: Azure Databricks | D62: AI
A63: Service | B63: Microsoft Fabric | C63: Microsoft Fabric | D63: Data
A64: Service | B64: Azure App Service | C64: Azure App Service | D64: Compute
A65: Service | B65: Azure Virtual Desktop | C65: Azure Virtual Desktop | D65: End-User Computing
A66: Service | B66: Azure Networking | C66: Azure Networking | D66: Networking
... A72: Service | B72: Azure Data Factory | C72: Azure Data Factory | D72: Data
A73: FiscalYear | B73: FY2024 | C73: FY2024 | D73: 45108 | E73: 45473 | F73: Microsoft fiscal year (July-June)
...
