Workbook

Sheet Readme
A1: Section | B1: Item | C1: Detail
A2: Overview | B2: File name | C2: MSX_Opportunities_Pipeline.xlsx
A3: Overview | B3: Purpose | C3: One of three synthetic datasets that will be parsed by an AI agent to answer questions about a customer's future Azure capacity needs, flag capacity risks, and recommend proactive actions. The companion files simulate Stratus capacity and CX Observe inventory/ACR.
A4: Overview | B4: Data notice | C4: SYNTHETIC DATA - for demo/testing only. No real customer, opportunity, revenue or capacity information is contained in this workbook.
A5: Overview | B5: Source system | C5: MSX (Microsoft Sales Experience) - simulated extract
A6: Overview | B6: Generation date | C6: 46280
A7: Overview | B7: Currency | C7: All monetary values are USD
A8: Overview | B8: Machine-readability | C8: Every data sheet is a flat table: one header row at row 1, no merged cells, no blank spacer rows or columns, consistent column names, real Excel dates and numbers, frozen header row and autofilter enabled.
A9: Join keys | B9: Customer join | C9: CustomerID - joins Customers, Opportunities and Opportunity_SKU_Demand in this file to the customer dimension in the Stratus capacity and CX Observe files.
A10: Join keys | B10: Capacity join | C10: Region + AvailabilityZone + VMSKU - the composite key used to join Opportunity_SKU_Demand and Demand_Summary_by_Region_SKU to available capacity in the Stratus file.
A11: Join keys | B11: Opportunity join | C11: OpportunityID - joins Opportunity_SKU_Demand to Opportunities (every OpportunityID in the demand sheet exists in Opportunities).
A12: Join keys | B12: Controlled vocabularies | C12: Reference_Data holds the authoritative lists of Region, AvailabilityZone, VMSKU (with vCPUs, memory, family, GPU flag), Stage, WorkloadType, SolutionArea, RiskFlag, DeploymentWave, Criticality and Segment values used in this file.
A13: Sheet inventory | B13: Readme | C13: This sheet: purpose, source, generation date, sheet inventory, column dictionary, join keys and data notice.
A14: Sheet inventory | B14: Customers | C14: 8 rows. Customer dimension with account team, current ACR and contract renewal date.
A15: Sheet inventory | B15: Opportunities | C15: 40 rows. Pipeline opportunities OPP-2026-0001 to OPP-2026-0040 across all 8 customers.
A16: Sheet inventory | B16: Opportunity_SKU_Demand | C16: 194 rows. Core join table: per-opportunity VM SKU demand by Region and AvailabilityZone.
A17: Sheet inventory | B17: Demand_Summary_by_Region_SKU | C17: 149 rows. SUMIFS rollup of required VM count and cores by Region + AvailabilityZone + VMSKU.
A18: Sheet inventory | B18: Reference_Data | C18: Controlled vocabulary / validation lists for the parsing agent.
... A73: Column dictionary: Reference_Data | B73: Notes | C73: Text. Free-text note about the value.

Sheet Customers
A1: CustomerID | B1: CustomerName | C1: Industry | D1: Segment | E1: AccountOwner | F1: TAM_CSAM | G1: CurrentAnnualACR_USD | H1: ContractRenewalDate
A2: CUST-001 | B2: Hellenic Bank of Attica | C2: Financial Services | D2: Enterprise | E2: Maria Kollias | F2: Andreas Voulgaris | G2: 11800000 | H2: 46477
A3: CUST-002 | B3: Aegean Retail Group | C3: Retail | D3: Enterprise | E3: Nikos Varelas | F3: Katerina Sideri | G3: 6450000 | H3: 46356
A4: CUST-003 | B4: Olympus Energy SA | C4: Energy | D4: Enterprise | E4: Elena Drakou | F4: Petros Kalogeras | G4: 8900000 | H4: 46568
A5: CUST-004 | B5: Delphi Logistics | C5: Transportation | D5: Corporate | E5: Stefanos Iliadis | F5: Ioanna Zafeiri | G5: 1750000 | H5: 46418
A6: CUST-005 | B6: Ionian Telecom | C6: Telco | D6: Enterprise | E6: Chryssa Petrou | F6: Christos Roussos | G6: 9600000 | H6: 46387
A7: CUST-006 | B7: Thessaly AgriTech | C7: Manufacturing | D7: Corporate | E7: Dimitris Anagnos | F7: Lena Papamichail | G7: 1250000 | H7: 46630
A8: CUST-007 | B8: Kyklades Media Group | C8: Media | D8: Corporate | E8: Sofia Lambrou | F8: Alexis Fotiadis | G8: 930000 | H8: 46446
A9: CUST-008 | B9: Piraeus Maritime Services | C9: Maritime | D9: Enterprise | E9: Yiannis Metaxas | F9: Despina Kranou | G9: 3400000 | H9: 46326

Sheet Opportunities
A1: OpportunityID | B1: CustomerID | C1: CustomerName | D1: OpportunityName | E1: SolutionArea | F1: Stage | G1: Probability_Pct | H1: EstimatedACR_USD | I1: EstimatedConsumptionStart | J1: EstimatedCloseDate | K1: DealValue_USD | L1: PrimaryRegion | M1: SecondaryRegion | N1: OpportunityOwner | O1: RiskFlag | P1: LastModified
A2: OPP-2026-0001 | B2: CUST-001 | C2: Hellenic Bank of Attica | D2: Core Banking Modernisation — Phase 2 | E2: Azure Infra | F2: Closed Won | G2: 100 | H2: 1900000 | I2: 46401 | J2: 46358 | K2: 4180000 | L2: UK South | M2: West Europe | N2: Nikos Varelas | O2: Budget | P2: 46262
A3: OPP-2026-0003 | B3: CUST-001 | C3: Hellenic Bank of Attica | D3: Risk & Regulatory Data Lakehouse | E3: Data & AI | F3: Closed Won | G3: 100 | H3: 180000 | I3: 46549 | J3: 46461 | K3: 503999 | L3: Sweden Central | M3: Poland Central | N3: Stefanos Iliadis | O3: None | P3: 46253
A4: OPP-2026-0008 | B4: CUST-002 | C4: Aegean Retail Group | D4: Retail Demand Forecasting Platform | E4: Data & AI | F4: Closed Won | G4: 100 | H4: 3100000 | I4: 46498 | J4: 46384 | K4: 8680000 | L4: West Europe | M4: Sweden Central | N4: Maria Kollias | O4: None | P4: 46274
A5: OPP-2026-0010 | B5: CUST-002 | C5: Aegean Retail Group | D5: Store Edge Analytics Rollout | E5: Data & AI | F5: Closed Won | G5: 100 | H5: 880000 | I5: 46498 | J5: 46452 | K5: 2640000 | L5: Greece Central | M5: Sweden Central | N5: Elena Drakou | O5: Timeline | P5: 46273
A6: OPP-2026-0022 | B6: CUST-005 | C6: Ionian Telecom | D6: Network Digital Twin Simulation | E6: Data & AI | F6: Closed Won | G6: 100 | H6: 1900000 | I6: 46448 | J6: 46337 | K6: 4750000 | L6: North Europe | M6: Italy North | N6: Sofia Lambrou | O6: None | P6: 46268
A7: OPP-2026-0027 | B7: CUST-005 | C7: Ionian Telecom | D7: AVD Estate Refresh | E7: Azure Infra | F7: Closed Won | G7: 100 | H7: 1480000 | I7: 46618 | J7: 46541 | K7: 4143999 | L7: Greece Central | M7: Italy North | N7: Stefanos Iliadis | O7: None | P7: 46247
A8: OPP-2026-0035 | B8: CUST-007 | C8: Kyklades Media Group | D8: Live Streaming Platform Build-out | E8: Digital & App Innovation | F8: Closed Won | G8: 100 | H8: 560000 | I8: 46309 | J8: 46275 | K8: 1400000 | L8: France Central | M8: Italy North | N8: Stefanos Iliadis | O8: Budget | P8: 46240
A9: OPP-2026-0036 | B9: CUST-008 | C9: Piraeus Maritime Services | D9: Port Operations Data Platform | E9: Data & AI | F9: Closed Won | G9: 100 | H9: 560000 | I9: 46540 | J9: 46449 | K9: 1400000 | L9: Germany West Central | M9: Sweden Central | N9: Chryssa Petrou | O9: None | P9: 46256
A10: OPP-2026-0011 | B10: CUST-002 | C10: Aegean Retail Group | D10: Customer 360 Data Platform | E10: Data & AI | F10: Commit | G10: 85 | H10: 1480000 | I10: 46323 | J10: 46263 | K10: 4143999 | L10: Sweden Central | M10: Switzerland North | N10: Stefanos Iliadis | O10: None | P10: 46274
A11: OPP-2026-0023 | B11: CUST-005 | C11: Ionian Telecom | D11: Telco AI Inference Fabric | E11: Data & AI | F11: Commit | G11: 85 | H11: 3100000 | I11: 46382 | J11: 46352 | K11: 9300000 | L11: West Europe | M11: UK South | N11: Yiannis Metaxas | O11: Capacity | P11: 46238
A12: OPP-2026-0026 | B12: CUST-005 | C12: Ionian Telecom | D12: Churn Prediction Model Factory | E12: Data & AI | F12: Commit | G12: 85 | H12: 2400000 | I12: 46521 | J12: 46424 | K12: 7200000 | L12: West Europe | M12: Sweden Central | N12: Elena Drakou | O12: Budget | P12: 46266
A13: OPP-2026-0029 | B13: CUST-006 | C13: Thessaly AgriTech | D13: IoT Sensor Data Platform | E13: Data & AI | F13: Commit | G13: 85 | H13: 1150000 | I13: 46381 | J13: 46265 | K13: 2530000 | L13: Germany West Central | M13: Poland Central | N13: Dimitris Anagnos | O13: None | P13: 46251
... A41: OPP-2026-0039 | B41: CUST-008 | C41: Piraeus Maritime Services | D41: Kubernetes Platform Build-out | E41: Digital & App Innovation | F41: Qualify | G41: 10 | H41: 1480000 | I41: 46296 | J41: 46210 | K41: 3700000 | L41: Greece Central | M41: UK South | N41: Yiannis Metaxas | O41: Budget | P41: 46240

Sheet Opportunity_SKU_Demand
A1: DemandID | B1: OpportunityID | C1: CustomerID | D1: Region | E1: AvailabilityZone | F1: VMSKU | G1: vCPUsPerVM | H1: RequiredVMCount | I1: RequiredCores | J1: RequiredMemoryGB | K1: DeploymentWave | L1: RequiredByDate | M1: WorkloadType | N1: IsZoneRedundant | O1: Criticality | P1: QuotaRequested
A2: DEM-0001 | B2: OPP-2026-0001 | C2: CUST-001 | D2: West Europe | E2: AZ-1 | F2: Standard_D16s_v5 | G2: 16 | H2: 40 | I2: =G2*H2 -> 640 | J2: 2560 | K2: Wave 1 | L2: 46419 | M2: General Purpose | N2: Yes | O2: Medium | P2: No
A3: DEM-0002 | B3: OPP-2026-0001 | C3: CUST-001 | D3: West Europe | E3: AZ-2 | F3: Standard_E64ds_v5 | G3: 64 | H3: 30 | I3: =G3*H3 -> 1920 | J3: 15360 | K3: Wave 2 | L3: 46468 | M3: Memory Optimised | N3: Yes | O3: Low | P3: Yes
A4: DEM-0003 | B4: OPP-2026-0001 | C4: CUST-001 | D4: UK South | E4: AZ-1 | F4: Standard_D8s_v5 | G4: 8 | H4: 40 | I4: =G4*H4 -> 320 | J4: 1280 | K4: Wave 1 | L4: 46402 | M4: General Purpose | N4: No | O4: Low | P4: Yes
A5: DEM-0004 | B5: OPP-2026-0001 | C5: CUST-001 | D5: UK South | E5: AZ-3 | F5: Standard_D64s_v5 | G5: 64 | H5: 60 | I5: =G5*H5 -> 3840 | J5: 15360 | K5: Wave 1 | L5: 46408 | M5: General Purpose | N5: Yes | O5: High | P5: Yes
A6: DEM-0005 | B6: OPP-2026-0001 | C6: CUST-001 | D6: West Europe | E6: AZ-2 | F6: Standard_D64s_v5 | G6: 64 | H6: 75 | I6: =G6*H6 -> 4800 | J6: 19200 | K6: Wave 3 | L6: 46548 | M6: General Purpose | N6: No | O6: Low | P6: No
A7: DEM-0006 | B7: OPP-2026-0002 | C7: CUST-001 | D7: West Europe | E7: AZ-2 | F7: Standard_ND96isr_H100_v5 | G7: 96 | H7: 20 | I7: =G7*H7 -> 1920 | J7: 38000 | K7: Wave 2 | L7: 46442 | M7: GPU-AI Training | N7: No | O7: High | P7: No
A8: DEM-0007 | B8: OPP-2026-0002 | C8: CUST-001 | D8: West Europe | E8: AZ-3 | F8: Standard_ND96isr_H100_v5 | G8: 96 | H8: 20 | I8: =G8*H8 -> 1920 | J8: 38000 | K8: Wave 3 | L8: 46528 | M8: GPU-AI Training | N8: Yes | O8: High | P8: No
A9: DEM-0008 | B9: OPP-2026-0002 | C9: CUST-001 | D9: West Europe | E9: AZ-1 | F9: Standard_D32s_v5 | G9: 32 | H9: 60 | I9: =G9*H9 -> 1920 | J9: 7680 | K9: Wave 2 | L9: 46442 | M9: General Purpose | N9: Yes | O9: Low | P9: No
A10: DEM-0009 | B10: OPP-2026-0002 | C10: CUST-001 | D10: West Europe | E10: AZ-3 | F10: Standard_D8s_v5 | G10: 8 | H10: 120 | I10: =G10*H10 -> 960 | J10: 3840 | K10: Wave 3 | L10: 46541 | M10: General Purpose | N10: Yes | O10: Low | P10: Yes
A11: DEM-0010 | B11: OPP-2026-0002 | C11: CUST-001 | D11: Sweden Central | E11: AZ-2 | F11: Standard_D32s_v5 | G11: 32 | H11: 24 | I11: =G11*H11 -> 768 | J11: 3072 | K11: Wave 3 | L11: 46538 | M11: General Purpose | N11: Yes | O11: High | P11: No
A12: DEM-0011 | B12: OPP-2026-0003 | C12: CUST-001 | D12: Sweden Central | E12: AZ-3 | F12: Standard_M128ms | G12: 128 | H12: 3 | I12: =G12*H12 -> 384 | J12: 11676 | K12: Wave 2 | L12: 46620 | M12: SAP | N12: Yes | O12: Medium | P12: No
A13: DEM-0012 | B13: OPP-2026-0003 | C13: CUST-001 | D13: Sweden Central | E13: AZ-2 | F13: Standard_M128ms | G13: 128 | H13: 2 | I13: =G13*H13 -> 256 | J13: 7784 | K13: Wave 2 | L13: 46614 | M13: SAP | N13: No | O13: Low | P13: No
... A195: DEM-0194 | B195: OPP-2026-0040 | C195: CUST-008 | D195: Germany West Central | E195: AZ-2 | F195: Standard_D8s_v5 | G195: 8 | H195: 24 | I195: =G195*H195 -> 192 | J195: 768 | K195: Wave 3 | L195: 46457 | M195: General Purpose | N195: Yes | O195: Low | P195: Yes

Sheet Demand_Summary_by_Region_SKU
A1: Region | B1: AvailabilityZone | C1: VMSKU | D1: vCPUsPerVM | E1: TotalRequiredVMCount | F1: TotalRequiredCores | G1: DemandLineCount
A2: France Central | B2: AZ-1 | C2: Standard_E16s_v5 | D2: 16 | E2: =SUMIFS(Opportunity_SKU_Demand!$H$2:$H$195,Opportunity_SKU_Demand!$D$2:$D$195,$A2,Opportunity_SKU_Demand!$E$2:$E$195,$B2,Opportunity_SKU_Demand!$F$2:$F$195,$C2) -> 20 | F2: =SUMIFS(Opportunity_SKU_Demand!$I$2:$I$195,Opportunity_SKU_Demand!$D$2:$D$195,$A2,Opportunity_SKU_Demand!$E$2:$E$195,$B2,Opportunity_SKU_Demand!$F$2:$F$195,$C2) -> 320 | G2: =COUNTIFS(Opportunity_SKU_Demand!$D$2:$D$195,$A2,Opportunity_SKU_Demand!$E$2:$E$195,$B2,Opportunity_SKU_Demand!$F$2:$F$195,$C2) -> 1
A3: France Central | B3: AZ-1 | C3: Standard_E32as_v6 | D3: 32 | E3: =SUMIFS(Opportunity_SKU_Demand!$H$2:$H$195,Opportunity_SKU_Demand!$D$2:$D$195,$A3,Opportunity_SKU_Demand!$E$2:$E$195,$B3,Opportunity_SKU_Demand!$F$2:$F$195,$C3) -> 48 | F3: =SUMIFS(Opportunity_SKU_Demand!$I$2:$I$195,Opportunity_SKU_Demand!$D$2:$D$195,$A3,Opportunity_SKU_Demand!$E$2:$E$195,$B3,Opportunity_SKU_Demand!$F$2:$F$195,$C3) -> 1536 | G3: =COUNTIFS(Opportunity_SKU_Demand!$D$2:$D$195,$A3,Opportunity_SKU_Demand!$E$2:$E$195,$B3,Opportunity_SKU_Demand!$F$2:$F$195,$C3) -> 1
A4: France Central | B4: AZ-1 | C4: Standard_HB176rs_v4 | D4: 176 | E4: =SUMIFS(Opportunity_SKU_Demand!$H$2:$H$195,Opportunity_SKU_Demand!$D$2:$D$195,$A4,Opportunity_SKU_Demand!$E$2:$E$195,$B4,Opportunity_SKU_Demand!$F$2:$F$195,$C4) -> 12 | F4: =SUMIFS(Opportunity_SKU_Demand!$I$2:$I$195,Opportunity_SKU_Demand!$D$2:$D$195,$A4,Opportunity_SKU_Demand!$E$2:$E$195,$B4,Opportunity_SKU_Demand!$F$2:$F$195,$C4) -> 2112 | G4: =COUNTIFS(Opportunity_SKU_Demand!$D$2:$D$195,$A4,Opportunity_SKU_Demand!$E$2:$E$195,$B4,Opportunity_SKU_Demand!$F$2:$F$195,$C4) -> 1
A5: France Central | B5: AZ-1 | C5: Standard_L16s_v3 | D5: 16 | E5: =SUMIFS(Opportunity_SKU_Demand!$H$2:$H$195,Opportunity_SKU_Demand!$D$2:$D$195,$A5,Opportunity_SKU_Demand!$E$2:$E$195,$B5,Opportunity_SKU_Demand!$F$2:$F$195,$C5) -> 75 | F5: =SUMIFS(Opportunity_SKU_Demand!$I$2:$I$195,Opportunity_SKU_Demand!$D$2:$D$195,$A5,Opportunity_SKU_Demand!$E$2:$E$195,$B5,Opportunity_SKU_Demand!$F$2:$F$195,$C5) -> 1200 | G5: =COUNTIFS(Opportunity_SKU_Demand!$D$2:$D$195,$A5,Opportunity_SKU_Demand!$E$2:$E$195,$B5,Opportunity_SKU_Demand!$F$2:$F$195,$C5) -> 1
A6: France Central | B6: AZ-2 | C6: Standard_D16s_v5 | D6: 16 | E6: =SUMIFS(Opportunity_SKU_Demand!$H$2:$H$195,Opportunity_SKU_Demand!$D$2:$D$195,$A6,Opportunity_SKU_Demand!$E$2:$E$195,$B6,Opportunity_SKU_Demand!$F$2:$F$195,$C6) -> 80 | F6: =SUMIFS(Opportunity_SKU_Demand!$I$2:$I$195,Opportunity_SKU_Demand!$D$2:$D$195,$A6,Opportunity_SKU_Demand!$E$2:$E$195,$B6,Opportunity_SKU_Demand!$F$2:$F$195,$C6) -> 1280 | G6: =COUNTIFS(Opportunity_SKU_Demand!$D$2:$D$195,$A6,Opportunity_SKU_Demand!$E$2:$E$195,$B6,Opportunity_SKU_Demand!$F$2:$F$195,$C6) -> 2
A7: France Central | B7: AZ-2 | C7: Standard_D32s_v5 | D7: 32 | E7: =SUMIFS(Opportunity_SKU_Demand!$H$2:$H$195,Opportunity_SKU_Demand!$D$2:$D$195,$A7,Opportunity_SKU_Demand!$E$2:$E$195,$B7,Opportunity_SKU_Demand!$F$2:$F$195,$C7) -> 48 | F7: =SUMIFS(Opportunity_SKU_Demand!$I$2:$I$195,Opportunity_SKU_Demand!$D$2:$D$195,$A7,Opportunity_SKU_Demand!$E$2:$E$195,$B7,Opportunity_SKU_Demand!$F$2:$F$195,$C7) -> 1536 | G7: =COUNTIFS(Opportunity_SKU_Demand!$D$2:$D$195,$A7,Opportunity_SKU_Demand!$E$2:$E$195,$B7,Opportunity_SKU_Demand!$F$2:$F$195,$C7) -> 1
A8: France Central | B8: AZ-2 | C8: Standard_D64s_v5 | D8: 64 | E8: =SUMIFS(Opportunity_SKU_Demand!$H$2:$H$195,Opportunity_SKU_Demand!$D$2:$D$195,$A8,Opportunity_SKU_Demand!$E$2:$E$195,$B8,Opportunity_SKU_Demand!$F$2:$F$195,$C8) -> 20 | F8: =SUMIFS(Opportunity_SKU_Demand!$I$2:$I$195,Opportunity_SKU_Demand!$D$2:$D$195,$A8,Opportunity_SKU_Demand!$E$2:$E$195,$B8,Opportunity_SKU_Demand!$F$2:$F$195,$C8) -> 1280 | G8: =COUNTIFS(Opportunity_SKU_Demand!$D$2:$D$195,$A8,Opportunity_SKU_Demand!$E$2:$E$195,$B8,Opportunity_SKU_Demand!$F$2:$F$195,$C8) -> 1
A9: France Central | B9: AZ-2 | C9: Standard_D8s_v5 | D9: 8 | E9: =SUMIFS(Opportunity_SKU_Demand!$H$2:$H$195,Opportunity_SKU_Demand!$D$2:$D$195,$A9,Opportunity_SKU_Demand!$E$2:$E$195,$B9,Opportunity_SKU_Demand!$F$2:$F$195,$C9) -> 70 | F9: =SUMIFS(Opportunity_SKU_Demand!$I$2:$I$195,Opportunity_SKU_Demand!$D$2:$D$195,$A9,Opportunity_SKU_Demand!$E$2:$E$195,$B9,Opportunity_SKU_Demand!$F$2:$F$195,$C9) -> 560 | G9: =COUNTIFS(Opportunity_SKU_Demand!$D$2:$D$195,$A9,Opportunity_SKU_Demand!$E$2:$E$195,$B9,Opportunity_SKU_Demand!$F$2:$F$195,$C9) -> 2
A10: France Central | B10: AZ-2 | C10: Standard_E16s_v5 | D10: 16 | E10: =SUMIFS(Opportunity_SKU_Demand!$H$2:$H$195,Opportunity_SKU_Demand!$D$2:$D$195,$A10,Opportunity_SKU_Demand!$E$2:$E$195,$B10,Opportunity_SKU_Demand!$F$2:$F$195,$C10) -> 90 | F10: =SUMIFS(Opportunity_SKU_Demand!$I$2:$I$195,Opportunity_SKU_Demand!$D$2:$D$195,$A10,Opportunity_SKU_Demand!$E$2:$E$195,$B10,Opportunity_SKU_Demand!$F$2:$F$195,$C10) -> 1440 | G10: =COUNTIFS(Opportunity_SKU_Demand!$D$2:$D$195,$A10,Opportunity_SKU_Demand!$E$2:$E$195,$B10,Opportunity_SKU_Demand!$F$2:$F$195,$C10) -> 1
A11: France Central | B11: AZ-2 | C11: Standard_E32ds_v5 | D11: 32 | E11: =SUMIFS(Opportunity_SKU_Demand!$H$2:$H$195,Opportunity_SKU_Demand!$D$2:$D$195,$A11,Opportunity_SKU_Demand!$E$2:$E$195,$B11,Opportunity_SKU_Demand!$F$2:$F$195,$C11) -> 10 | F11: =SUMIFS(Opportunity_SKU_Demand!$I$2:$I$195,Opportunity_SKU_Demand!$D$2:$D$195,$A11,Opportunity_SKU_Demand!$E$2:$E$195,$B11,Opportunity_SKU_Demand!$F$2:$F$195,$C11) -> 320 | G11: =COUNTIFS(Opportunity_SKU_Demand!$D$2:$D$195,$A11,Opportunity_SKU_Demand!$E$2:$E$195,$B11,Opportunity_SKU_Demand!$F$2:$F$195,$C11) -> 1
A12: France Central | B12: AZ-2 | C12: Standard_F32s_v2 | D12: 32 | E12: =SUMIFS(Opportunity_SKU_Demand!$H$2:$H$195,Opportunity_SKU_Demand!$D$2:$D$195,$A12,Opportunity_SKU_Demand!$E$2:$E$195,$B12,Opportunity_SKU_Demand!$F$2:$F$195,$C12) -> 75 | F12: =SUMIFS(Opportunity_SKU_Demand!$I$2:$I$195,Opportunity_SKU_Demand!$D$2:$D$195,$A12,Opportunity_SKU_Demand!$E$2:$E$195,$B12,Opportunity_SKU_Demand!$F$2:$F$195,$C12) -> 2400 | G12: =COUNTIFS(Opportunity_SKU_Demand!$D$2:$D$195,$A12,Opportunity_SKU_Demand!$E$2:$E$195,$B12,Opportunity_SKU_Demand!$F$2:$F$195,$C12) -> 1
A13: France Central | B13: AZ-2 | C13: Standard_M128ms | D13: 128 | E13: =SUMIFS(Opportunity_SKU_Demand!$H$2:$H$195,Opportunity_SKU_Demand!$D$2:$D$195,$A13,Opportunity_SKU_Demand!$E$2:$E$195,$B13,Opportunity_SKU_Demand!$F$2:$F$195,$C13) -> 6 | F13: =SUMIFS(Opportunity_SKU_Demand!$I$2:$I$195,Opportunity_SKU_Demand!$D$2:$D$195,$A13,Opportunity_SKU_Demand!$E$2:$E$195,$B13,Opportunity_SKU_Demand!$F$2:$F$195,$C13) -> 768 | G13: =COUNTIFS(Opportunity_SKU_Demand!$D$2:$D$195,$A13,Opportunity_SKU_Demand!$E$2:$E$195,$B13,Opportunity_SKU_Demand!$F$2:$F$195,$C13) -> 1
... A150: West Europe | B150: AZ-3 | C150: Standard_ND96isr_H100_v5 | D150: 96 | E150: =SUMIFS(Opportunity_SKU_Demand!$H$2:$H$195,Opportunity_SKU_Demand!$D$2:$D$195,$A150,Opportunity_SKU_Demand!$E$2:$E$195,$B150,Opportunity_SKU_Demand!$F$2:$F$195,$C150) -> 78 | F150: =SUMIFS(Opportunity_SKU_Demand!$I$2:$I$195,Opportunity_SKU_Demand!$D$2:$D$195,$A150,Opportunity_SKU_Demand!$E$2:$E$195,$B150,Opportunity_SKU_Demand!$F$2:$F$195,$C150) -> 7488 | G150: =COUNTIFS(Opportunity_SKU_Demand!$D$2:$D$195,$A150,Opportunity_SKU_Demand!$E$2:$E$195,$B150,Opportunity_SKU_Demand!$F$2:$F$195,$C150) -> 4

Sheet Reference_Data
A1: RefType | B1: Value | C1: ParentRegion | D1: vCPUs | E1: MemoryGB | F1: Family | G1: IsGPU | H1: Notes
A2: Region | B2: West Europe | H2: Azure region in scope for this dataset
A3: Region | B3: North Europe | H3: Azure region in scope for this dataset
A4: Region | B4: Sweden Central | H4: Azure region in scope for this dataset
A5: Region | B5: Germany West Central | H5: Azure region in scope for this dataset
A6: Region | B6: Italy North | H6: Azure region in scope for this dataset
A7: Region | B7: UK South | H7: Azure region in scope for this dataset
A8: Region | B8: France Central | H8: Azure region in scope for this dataset
A9: Region | B9: Switzerland North | H9: Azure region in scope for this dataset
A10: Region | B10: Poland Central | H10: Azure region in scope for this dataset
A11: Region | B11: Greece Central | H11: Azure region in scope for this dataset
A12: AvailabilityZone | B12: AZ-1 | C12: West Europe | H12: Logical availability zone
A13: AvailabilityZone | B13: AZ-2 | C13: West Europe | H13: Logical availability zone
A14: AvailabilityZone | B14: AZ-3 | C14: West Europe | H14: Logical availability zone
A15: AvailabilityZone | B15: AZ-1 | C15: North Europe | H15: Logical availability zone
A16: AvailabilityZone | B16: AZ-2 | C16: North Europe | H16: Logical availability zone
A17: AvailabilityZone | B17: AZ-3 | C17: North Europe | H17: Logical availability zone
A18: AvailabilityZone | B18: AZ-1 | C18: Sweden Central | H18: Logical availability zone
A19: AvailabilityZone | B19: AZ-2 | C19: Sweden Central | H19: Logical availability zone
A20: AvailabilityZone | B20: AZ-3 | C20: Sweden Central | H20: Logical availability zone
A21: AvailabilityZone | B21: AZ-1 | C21: Germany West Central | H21: Logical availability zone
A22: AvailabilityZone | B22: AZ-2 | C22: Germany West Central | H22: Logical availability zone
A23: AvailabilityZone | B23: AZ-3 | C23: Germany West Central | H23: Logical availability zone
... A40: AvailabilityZone | B40: AZ-2 | C40: Greece Central | H40: Logical availability zone
A41: VMSKU | B41: Standard_D8s_v5 | D41: 8 | E41: 32 | F41: Dv5 | G41: No | H41: Default workload type: General Purpose
A42: VMSKU | B42: Standard_D16s_v5 | D42: 16 | E42: 64 | F42: Dv5 | G42: No | H42: Default workload type: General Purpose
A43: VMSKU | B43: Standard_D32s_v5 | D43: 32 | E43: 128 | F43: Dv5 | G43: No | H43: Default workload type: General Purpose
A44: VMSKU | B44: Standard_D64s_v5 | D44: 64 | E44: 256 | F44: Dv5 | G44: No | H44: Default workload type: General Purpose
A45: VMSKU | B45: Standard_E16s_v5 | D45: 16 | E45: 128 | F45: Ev5 | G45: No | H45: Default workload type: Memory Optimised
A46: VMSKU | B46: Standard_E32ds_v5 | D46: 32 | E46: 256 | F46: Ev5 | G46: No | H46: Default workload type: Memory Optimised
A47: VMSKU | B47: Standard_E64ds_v5 | D47: 64 | E47: 512 | F47: Ev5 | G47: No | H47: Default workload type: Memory Optimised
A48: VMSKU | B48: Standard_F32s_v2 | D48: 32 | E48: 64 | F48: Fsv2 | G48: No | H48: Default workload type: Compute Optimised
A49: VMSKU | B49: Standard_L16s_v3 | D49: 16 | E49: 128 | F49: Lsv3 | G49: No | H49: Default workload type: Storage Optimised
A50: VMSKU | B50: Standard_M128ms | D50: 128 | E50: 3892 | F50: Mv2 | G50: No | H50: Default workload type: SAP
A51: VMSKU | B51: Standard_D16as_v6 | D51: 16 | E51: 64 | F51: Dasv6 | G51: No | H51: Default workload type: General Purpose
A52: VMSKU | B52: Standard_E32as_v6 | D52: 32 | E52: 256 | F52: Easv6 | G52: No | H52: Default workload type: Memory Optimised
... A56: VMSKU | B56: Standard_NC40ads_H100_v5 | D56: 40 | E56: 320 | F56: NCads_H100_v5 | G56: Yes | H56: Default workload type: GPU-AI Inference
A57: Stage | B57: Qualify | H57: MSX sales stage; Probability_Pct = 10
A58: Stage | B58: Develop | H58: MSX sales stage; Probability_Pct = 25
A59: Stage | B59: Propose | H59: MSX sales stage; Probability_Pct = 45
...
